<?xml version="1.0" encoding="UTF-8"?>
<testng-results skipped="0" failed="5" ignored="0" total="6" passed="1">
  <reporter-output>
  </reporter-output>
  <suite name="Default suite" duration-ms="124" started-at="2017-02-22T19:50:40Z" finished-at="2017-02-22T19:50:40Z">
    <groups>
    </groups>
    <test name="Default test" duration-ms="124" started-at="2017-02-22T19:50:40Z" finished-at="2017-02-22T19:50:40Z">
      <class name="com.klindziuk.TriangleTestLab.GetSquareTest">
        <test-method status="FAIL" signature="getSquare_Test_NaN()[pri:0, instance:com.klindziuk.TriangleTestLab.GetSquareTest@10399e]" name="getSquare_Test_NaN" duration-ms="33" started-at="2017-02-22T21:50:40Z" finished-at="2017-02-22T21:50:40Z">
          <exception class="org.testng.TestException">
            <message>
              <![CDATA[
Method GetSquareTest.getSquare_Test_NaN()[pri:0, instance:com.klindziuk.TriangleTestLab.GetSquareTest@10399e] should have thrown an exception of type class java.lang.IllegalArgumentException]]>
            </message>
            <full-stacktrace>
              <![CDATA[org.testng.TestException: 
Method GetSquareTest.getSquare_Test_NaN()[pri:0, instance:com.klindziuk.TriangleTestLab.GetSquareTest@10399e] should have thrown an exception of type class java.lang.IllegalArgumentException
	at org.testng.internal.ExpectedExceptionsHolder.noException(ExpectedExceptionsHolder.java:89)
	at org.testng.internal.Invoker.handleInvocationResults(Invoker.java:1401)
	at org.testng.internal.Invoker.invokeMethod(Invoker.java:684)
	at org.testng.internal.Invoker.invokeTestMethod(Invoker.java:851)
	at org.testng.internal.Invoker.invokeTestMethods(Invoker.java:1177)
	at org.testng.internal.TestMethodWorker.invokeTestMethods(TestMethodWorker.java:129)
	at org.testng.internal.TestMethodWorker.run(TestMethodWorker.java:112)
	at org.testng.TestRunner.privateRun(TestRunner.java:756)
	at org.testng.TestRunner.run(TestRunner.java:610)
	at org.testng.SuiteRunner.runTest(SuiteRunner.java:387)
	at org.testng.SuiteRunner.runSequentially(SuiteRunner.java:382)
	at org.testng.SuiteRunner.privateRun(SuiteRunner.java:340)
	at org.testng.SuiteRunner.run(SuiteRunner.java:289)
	at org.testng.SuiteRunnerWorker.runSuite(SuiteRunnerWorker.java:52)
	at org.testng.SuiteRunnerWorker.run(SuiteRunnerWorker.java:86)
	at org.testng.TestNG.runSuitesSequentially(TestNG.java:1293)
	at org.testng.TestNG.runSuitesLocally(TestNG.java:1218)
	at org.testng.TestNG.runSuites(TestNG.java:1133)
	at org.testng.TestNG.run(TestNG.java:1104)
	at org.testng.remote.AbstractRemoteTestNG.run(AbstractRemoteTestNG.java:132)
	at org.testng.remote.RemoteTestNG.initAndRun(RemoteTestNG.java:236)
	at org.testng.remote.RemoteTestNG.main(RemoteTestNG.java:81)
]]>
            </full-stacktrace>
          </exception> <!-- org.testng.TestException -->
          <reporter-output>
          </reporter-output>
        </test-method> <!-- getSquare_Test_NaN -->
        <test-method status="FAIL" signature="getSquare_Test_NegativeInfinity()[pri:0, instance:com.klindziuk.TriangleTestLab.GetSquareTest@10399e]" name="getSquare_Test_NegativeInfinity" duration-ms="2" started-at="2017-02-22T21:50:40Z" finished-at="2017-02-22T21:50:40Z">
          <exception class="org.testng.TestException">
            <message>
              <![CDATA[
Method GetSquareTest.getSquare_Test_NegativeInfinity()[pri:0, instance:com.klindziuk.TriangleTestLab.GetSquareTest@10399e] should have thrown an exception of type class java.lang.IllegalArgumentException]]>
            </message>
            <full-stacktrace>
              <![CDATA[org.testng.TestException: 
Method GetSquareTest.getSquare_Test_NegativeInfinity()[pri:0, instance:com.klindziuk.TriangleTestLab.GetSquareTest@10399e] should have thrown an exception of type class java.lang.IllegalArgumentException
	at org.testng.internal.ExpectedExceptionsHolder.noException(ExpectedExceptionsHolder.java:89)
	at org.testng.internal.Invoker.handleInvocationResults(Invoker.java:1401)
	at org.testng.internal.Invoker.invokeMethod(Invoker.java:684)
	at org.testng.internal.Invoker.invokeTestMethod(Invoker.java:851)
	at org.testng.internal.Invoker.invokeTestMethods(Invoker.java:1177)
	at org.testng.internal.TestMethodWorker.invokeTestMethods(TestMethodWorker.java:129)
	at org.testng.internal.TestMethodWorker.run(TestMethodWorker.java:112)
	at org.testng.TestRunner.privateRun(TestRunner.java:756)
	at org.testng.TestRunner.run(TestRunner.java:610)
	at org.testng.SuiteRunner.runTest(SuiteRunner.java:387)
	at org.testng.SuiteRunner.runSequentially(SuiteRunner.java:382)
	at org.testng.SuiteRunner.privateRun(SuiteRunner.java:340)
	at org.testng.SuiteRunner.run(SuiteRunner.java:289)
	at org.testng.SuiteRunnerWorker.runSuite(SuiteRunnerWorker.java:52)
	at org.testng.SuiteRunnerWorker.run(SuiteRunnerWorker.java:86)
	at org.testng.TestNG.runSuitesSequentially(TestNG.java:1293)
	at org.testng.TestNG.runSuitesLocally(TestNG.java:1218)
	at org.testng.TestNG.runSuites(TestNG.java:1133)
	at org.testng.TestNG.run(TestNG.java:1104)
	at org.testng.remote.AbstractRemoteTestNG.run(AbstractRemoteTestNG.java:132)
	at org.testng.remote.RemoteTestNG.initAndRun(RemoteTestNG.java:236)
	at org.testng.remote.RemoteTestNG.main(RemoteTestNG.java:81)
]]>
            </full-stacktrace>
          </exception> <!-- org.testng.TestException -->
          <reporter-output>
          </reporter-output>
        </test-method> <!-- getSquare_Test_NegativeInfinity -->
        <test-method status="FAIL" signature="getSquare_Test_NegativeNumber()[pri:0, instance:com.klindziuk.TriangleTestLab.GetSquareTest@10399e]" name="getSquare_Test_NegativeNumber" duration-ms="2" started-at="2017-02-22T21:50:40Z" finished-at="2017-02-22T21:50:40Z">
          <exception class="junit.framework.AssertionFailedError">
            <message>
              <![CDATA[expected:<NaN> but was:<-0.0>]]>
            </message>
            <full-stacktrace>
              <![CDATA[junit.framework.AssertionFailedError: expected:<NaN> but was:<-0.0>
	at junit.framework.Assert.fail(Assert.java:47)
	at junit.framework.Assert.failNotEquals(Assert.java:282)
	at junit.framework.Assert.assertEquals(Assert.java:64)
	at junit.framework.Assert.assertEquals(Assert.java:71)
	at com.klindziuk.TriangleTestLab.GetSquareTest.getSquare_Test_NegativeNumber(GetSquareTest.java:42)
	at sun.reflect.NativeMethodAccessorImpl.invoke0(Native Method)
	at sun.reflect.NativeMethodAccessorImpl.invoke(Unknown Source)
	at sun.reflect.DelegatingMethodAccessorImpl.invoke(Unknown Source)
	at java.lang.reflect.Method.invoke(Unknown Source)
	at org.testng.internal.MethodInvocationHelper.invokeMethod(MethodInvocationHelper.java:104)
	at org.testng.internal.Invoker.invokeMethod(Invoker.java:645)
	at org.testng.internal.Invoker.invokeTestMethod(Invoker.java:851)
	at org.testng.internal.Invoker.invokeTestMethods(Invoker.java:1177)
	at org.testng.internal.TestMethodWorker.invokeTestMethods(TestMethodWorker.java:129)
	at org.testng.internal.TestMethodWorker.run(TestMethodWorker.java:112)
	at org.testng.TestRunner.privateRun(TestRunner.java:756)
	at org.testng.TestRunner.run(TestRunner.java:610)
	at org.testng.SuiteRunner.runTest(SuiteRunner.java:387)
	at org.testng.SuiteRunner.runSequentially(SuiteRunner.java:382)
	at org.testng.SuiteRunner.privateRun(SuiteRunner.java:340)
	at org.testng.SuiteRunner.run(SuiteRunner.java:289)
	at org.testng.SuiteRunnerWorker.runSuite(SuiteRunnerWorker.java:52)
	at org.testng.SuiteRunnerWorker.run(SuiteRunnerWorker.java:86)
	at org.testng.TestNG.runSuitesSequentially(TestNG.java:1293)
	at org.testng.TestNG.runSuitesLocally(TestNG.java:1218)
	at org.testng.TestNG.runSuites(TestNG.java:1133)
	at org.testng.TestNG.run(TestNG.java:1104)
	at org.testng.remote.AbstractRemoteTestNG.run(AbstractRemoteTestNG.java:132)
	at org.testng.remote.RemoteTestNG.initAndRun(RemoteTestNG.java:236)
	at org.testng.remote.RemoteTestNG.main(RemoteTestNG.java:81)
]]>
            </full-stacktrace>
          </exception> <!-- junit.framework.AssertionFailedError -->
          <reporter-output>
          </reporter-output>
        </test-method> <!-- getSquare_Test_NegativeNumber -->
        <test-method status="FAIL" signature="getSquare_Test_Null()[pri:0, instance:com.klindziuk.TriangleTestLab.GetSquareTest@10399e]" name="getSquare_Test_Null" duration-ms="3" started-at="2017-02-22T21:50:40Z" finished-at="2017-02-22T21:50:40Z">
          <exception class="junit.framework.AssertionFailedError">
            <message>
              <![CDATA[expected:<0.0> but was:<NaN>]]>
            </message>
            <full-stacktrace>
              <![CDATA[junit.framework.AssertionFailedError: expected:<0.0> but was:<NaN>
	at junit.framework.Assert.fail(Assert.java:47)
	at junit.framework.Assert.failNotEquals(Assert.java:282)
	at junit.framework.Assert.assertEquals(Assert.java:64)
	at junit.framework.Assert.assertEquals(Assert.java:71)
	at com.klindziuk.TriangleTestLab.GetSquareTest.getSquare_Test_Null(GetSquareTest.java:18)
	at sun.reflect.NativeMethodAccessorImpl.invoke0(Native Method)
	at sun.reflect.NativeMethodAccessorImpl.invoke(Unknown Source)
	at sun.reflect.DelegatingMethodAccessorImpl.invoke(Unknown Source)
	at java.lang.reflect.Method.invoke(Unknown Source)
	at org.testng.internal.MethodInvocationHelper.invokeMethod(MethodInvocationHelper.java:104)
	at org.testng.internal.Invoker.invokeMethod(Invoker.java:645)
	at org.testng.internal.Invoker.invokeTestMethod(Invoker.java:851)
	at org.testng.internal.Invoker.invokeTestMethods(Invoker.java:1177)
	at org.testng.internal.TestMethodWorker.invokeTestMethods(TestMethodWorker.java:129)
	at org.testng.internal.TestMethodWorker.run(TestMethodWorker.java:112)
	at org.testng.TestRunner.privateRun(TestRunner.java:756)
	at org.testng.TestRunner.run(TestRunner.java:610)
	at org.testng.SuiteRunner.runTest(SuiteRunner.java:387)
	at org.testng.SuiteRunner.runSequentially(SuiteRunner.java:382)
	at org.testng.SuiteRunner.privateRun(SuiteRunner.java:340)
	at org.testng.SuiteRunner.run(SuiteRunner.java:289)
	at org.testng.SuiteRunnerWorker.runSuite(SuiteRunnerWorker.java:52)
	at org.testng.SuiteRunnerWorker.run(SuiteRunnerWorker.java:86)
	at org.testng.TestNG.runSuitesSequentially(TestNG.java:1293)
	at org.testng.TestNG.runSuitesLocally(TestNG.java:1218)
	at org.testng.TestNG.runSuites(TestNG.java:1133)
	at org.testng.TestNG.run(TestNG.java:1104)
	at org.testng.remote.AbstractRemoteTestNG.run(AbstractRemoteTestNG.java:132)
	at org.testng.remote.RemoteTestNG.initAndRun(RemoteTestNG.java:236)
	at org.testng.remote.RemoteTestNG.main(RemoteTestNG.java:81)
]]>
            </full-stacktrace>
          </exception> <!-- junit.framework.AssertionFailedError -->
          <reporter-output>
          </reporter-output>
        </test-method> <!-- getSquare_Test_Null -->
        <test-method status="FAIL" signature="getSquare_Test_PositiveInfinity()[pri:0, instance:com.klindziuk.TriangleTestLab.GetSquareTest@10399e]" name="getSquare_Test_PositiveInfinity" duration-ms="2" started-at="2017-02-22T21:50:40Z" finished-at="2017-02-22T21:50:40Z">
          <exception class="org.testng.TestException">
            <message>
              <![CDATA[
Method GetSquareTest.getSquare_Test_PositiveInfinity()[pri:0, instance:com.klindziuk.TriangleTestLab.GetSquareTest@10399e] should have thrown an exception of type class java.lang.IllegalArgumentException]]>
            </message>
            <full-stacktrace>
              <![CDATA[org.testng.TestException: 
Method GetSquareTest.getSquare_Test_PositiveInfinity()[pri:0, instance:com.klindziuk.TriangleTestLab.GetSquareTest@10399e] should have thrown an exception of type class java.lang.IllegalArgumentException
	at org.testng.internal.ExpectedExceptionsHolder.noException(ExpectedExceptionsHolder.java:89)
	at org.testng.internal.Invoker.handleInvocationResults(Invoker.java:1401)
	at org.testng.internal.Invoker.invokeMethod(Invoker.java:684)
	at org.testng.internal.Invoker.invokeTestMethod(Invoker.java:851)
	at org.testng.internal.Invoker.invokeTestMethods(Invoker.java:1177)
	at org.testng.internal.TestMethodWorker.invokeTestMethods(TestMethodWorker.java:129)
	at org.testng.internal.TestMethodWorker.run(TestMethodWorker.java:112)
	at org.testng.TestRunner.privateRun(TestRunner.java:756)
	at org.testng.TestRunner.run(TestRunner.java:610)
	at org.testng.SuiteRunner.runTest(SuiteRunner.java:387)
	at org.testng.SuiteRunner.runSequentially(SuiteRunner.java:382)
	at org.testng.SuiteRunner.privateRun(SuiteRunner.java:340)
	at org.testng.SuiteRunner.run(SuiteRunner.java:289)
	at org.testng.SuiteRunnerWorker.runSuite(SuiteRunnerWorker.java:52)
	at org.testng.SuiteRunnerWorker.run(SuiteRunnerWorker.java:86)
	at org.testng.TestNG.runSuitesSequentially(TestNG.java:1293)
	at org.testng.TestNG.runSuitesLocally(TestNG.java:1218)
	at org.testng.TestNG.runSuites(TestNG.java:1133)
	at org.testng.TestNG.run(TestNG.java:1104)
	at org.testng.remote.AbstractRemoteTestNG.run(AbstractRemoteTestNG.java:132)
	at org.testng.remote.RemoteTestNG.initAndRun(RemoteTestNG.java:236)
	at org.testng.remote.RemoteTestNG.main(RemoteTestNG.java:81)
]]>
            </full-stacktrace>
          </exception> <!-- org.testng.TestException -->
          <reporter-output>
          </reporter-output>
        </test-method> <!-- getSquare_Test_PositiveInfinity -->
        <test-method status="PASS" signature="getSquare_Test_Valid()[pri:0, instance:com.klindziuk.TriangleTestLab.GetSquareTest@10399e]" name="getSquare_Test_Valid" duration-ms="2" started-at="2017-02-22T21:50:40Z" finished-at="2017-02-22T21:50:40Z">
          <reporter-output>
          </reporter-output>
        </test-method> <!-- getSquare_Test_Valid -->
      </class> <!-- com.klindziuk.TriangleTestLab.GetSquareTest -->
    </test> <!-- Default test -->
  </suite> <!-- Default suite -->
</testng-results>
